<?xml version="1.0"?>
<robot name="cylinder_sphere_robot">

  <!-- Cylinder link -->
  <link name="unit_cylinder">
    <visual>
      <geometry>
        <cylinder radius="0.5" length="1.0"/>
      </geometry>
      <material name="grey"/>
    </visual>
    <collision>
      <geometry>
        <cylinder radius="0.5" length="1.0"/>
      </geometry>
    </collision>
    <inertial>
      <mass value="1.0"/>
      <inertia ixx="0.145833" ixy="0" ixz="0" iyy="0.145833" iyz="0" izz="0.125"/>
      <origin xyz="0 0 0" rpy="0 0 0"/>
    </inertial>
  </link>

  <!-- Sphere link -->
  <link name="unit_sphere">
    <visual>
      <geometry>
        <sphere radius="0.5"/>
      </geometry>
      <material name="grey"/>
    </visual>
    <collision>
      <geometry>
        <sphere radius="0.5"/>
      </geometry>
    </collision>
    <inertial>
      <mass value="1.0"/>
      <inertia ixx="0.1" ixy="0" ixz="0" iyy="0.1" iyz="0" izz="0.1"/>
      <origin xyz="0 0 0" rpy="0 0 0"/>
    </inertial>
  </link>

  <!-- Fixed base to world -->
  <joint name="cylinder_fixed" type="fixed">
    <parent link="world"/>
    <child link="unit_cylinder"/>
    <origin xyz="0 0 0.5" rpy="0 0 0"/>
  </joint>

  <!-- Revolute joint between cylinder and sphere -->
  <joint name="sphere_to_cylinder_joint" type="revolute">
    <parent link="unit_cylinder"/>
    <child link="unit_sphere"/>
    <!-- Position the joint at the surface of the cylinder so sphere is half inserted -->
    <origin xyz="0.5 0 0" rpy="0 0 0"/>
    <axis xyz="1 0 0"/> <!-- rotation about X-axis -->
    <limit effort="100" velocity="10" lower="-3.14159" upper="3.14159"/>
    <dynamics damping="0.1" friction="0.1"/>
  </joint>

</robot>
